Workbook

Sheet Sheet1
A1: PartNumber | B1: partdesc | C1: AttributeID | D1: AttributeDesc | E1: Value
A2: N1WB E23942 BF1G1E | B2: P703 DOOR FRT DBL RH | C2: 33 | D2: VERTICAL INSERT | E2: ASYE23942FEBONY
A3: N1WB E23942 BF1G1E | B3: P703 DOOR FRT DBL RH | C3: 34 | D3: TOP ROLL | E3: ASY23900ASE
A4: N1WB E23942 BF1G1E | B4: P703 DOOR FRT DBL RH | C4: 35 | D4: APPLIQUE | E4: PCPE237W28APIA91
A5: N1WB E23942 BF1G1E | B5: P703 DOOR FRT DBL RH | C5: 36 | D5: AMBIENT LIGHT | E5: PCP14E072AD00P703
A6: N1WB E23942 BF1G1E | B6: P703 DOOR FRT DBL RH | C6: 37 | D6: IP EXTENSIION | E6: PCPE23942APIA20JA6
A7: N1WB E23942 BF1G1E | B7: P703 DOOR FRT DBL RH | C7: 38 | D7: LOCK SWITCH | E7: PCP14017E
A8: N1WB E23942 BF1G1E | B8: P703 DOOR FRT DBL RH | C8: 39 | D8: ARM REST | E8: PCPE23942AR02
A9: N1WB E23942 BF3LU4 | B9: P703 DOOR FRT DBL RH | C9: 33 | D9: VERTICAL INSERT | E9: ASYE23864APIA9103
A10: N1WB E23942 BF3LU4 | B10: P703 DOOR FRT DBL RH | C10: 34 | D10: TOP ROLL | E10: ASY23900ASE
A11: N1WB E23942 BF3LU4 | B11: P703 DOOR FRT DBL RH | C11: 35 | D11: APPLIQUE | E11: PCPE237W28APIA91
A12: N1WB E23942 BF3LU4 | B12: P703 DOOR FRT DBL RH | C12: 36 | D12: AMBIENT LIGHT | E12: PCP14E072AD00P703
A13: N1WB E23942 BF3LU4 | B13: P703 DOOR FRT DBL RH | C13: 37 | D13: IP EXTENSIION | E13: PCPE23942APIA20JA6
... A446: T1WB E27407 DB1HHY | B446: P703 DOOR REAR DBL LH | C446: 39 | D446: ARM REST | E446: PCPE27407AR08.H

Sheet Sheet6
A1: AttributeID | B1: AttributeDesc | C1: Value | D1: Inventory Lookup
A2: 33 | B2: VERTICAL INSERT | C2: ASYE23864APIA9102 | D2: #N/A
A3: 33 | B3: VERTICAL INSERT | C3: ASYE23864APIA9103 | D3: #N/A
A4: 33 | B4: VERTICAL INSERT | C4: ASYE23865APIA91 | D4: #N/A
A5: 33 | B5: VERTICAL INSERT | C5: ASYE23865APIA9102 | D5: #N/A
A6: 33 | B6: VERTICAL INSERT | C6: ASYE23865APIA9103 | D6: #N/A
A7: 33 | B7: VERTICAL INSERT | C7: ASYE23942FEBONY | D7: #N/A
A8: 33 | B8: VERTICAL INSERT | C8: ASYE27406BEBONY | D8: #N/A
A9: 33 | B9: VERTICAL INSERT | C9: ASYE27406SANDSTONE | D9: #N/A
A10: 33 | B10: VERTICAL INSERT | C10: ASYE27406SUPERMATTE | D10: #N/A
A11: 33 | B11: VERTICAL INSERT | C11: ASYE27407BEBONY | D11: #N/A
A12: 33 | B12: VERTICAL INSERT | C12: ASYE27407SANDSTONE | D12: #N/A
A13: 33 | B13: VERTICAL INSERT | C13: ASYE27407SUPERMATTE | D13: #N/A
A14: 33 | B14: VERTICAL INSERT | C14: ASYE7407SANDSTONE | D14: #N/A
A15: 33 | B15: VERTICAL INSERT | C15: PCPE23942IN01.H | D15: INSERT RH EBONY SOHO
A16: 33 | B16: VERTICAL INSERT | C16: PCPE23942IN02.H | D16: INSERT RH SAND SOHO
A17: 33 | B17: VERTICAL INSERT | C17: PCPE23942IN03.H | D17: INSERT RH EBONY SUPER SMOOTH
A18: 33 | B18: VERTICAL INSERT | C18: PCPE23943IN01.H | D18: P703 INSERT LH ENONY SOHO
A19: 33 | B19: VERTICAL INSERT | C19: PCPE23943IN02.H | D19: INSERT LH SAND SOHO
A20: 33 | B20: VERTICAL INSERT | C20: PCPE23943IN03.H | D20: INSERT LH EBONY SUPER SMOOTH
A21: 33 | B21: VERTICAL INSERT | C21: PCPE27406IN01.H | D21: P703 INSERT RH EBONY SOHO
A22: 33 | B22: VERTICAL INSERT | C22: PCPE27406IN02.H | D22: P703 INSERT RH SAND STONE
A23: 33 | B23: VERTICAL INSERT | C23: PCPE27406IN03.H | D23: P703 INSERT RH EBONY S.SMOOTH
A24: 33 | B24: VERTICAL INSERT | C24: PCPE27407IN01.H | D24: P703 INSERT LH EBONY SOHO
A25: 33 | B25: VERTICAL INSERT | C25: PCPE27407IN02.H | D25: P703 INSERT LH SAND SOHO
A26: 33 | B26: VERTICAL INSERT | C26: PCPE27407IN03.H | D26: P703 INSERT LH EBONY S.SMOOTH
A27: 34 | B27: TOP ROLL | C27: ASY23900ASE | D27: #N/A
A28: 34 | B28: TOP ROLL | C28: ASYE23900ABP | D28: P703 BLACK PACK VERSION.
A29: 34 | B29: TOP ROLL | C29: ASYE23900AMIC | D29: P703 Hard Top Roll W REINF
A30: 34 | B30: TOP ROLL | C30: ASYE23900ASE | D30: P703 Soho Ebony W/ Urban Gray
A31: 34 | B31: TOP ROLL | C31: ASYE23900ATS | D31: P703 Terra Suede Ebony W/ BLK
A32: 34 | B32: TOP ROLL | C32: ASYE23900HARDTOP | D32: #N/A
A33: 34 | B33: TOP ROLL | C33: ASYE23901ABP | D33: P703 BLACK PACK VERSION
A34: 34 | B34: TOP ROLL | C34: ASYE23901AMIC | D34: P703 Hard Top Roll W REINF
A35: 34 | B35: TOP ROLL | C35: ASYE23901ASE | D35: P703 Soho Ebony W/ Urban Gray
A36: 34 | B36: TOP ROLL | C36: ASYE23901ATS | D36: P703 Terra Suede Ebony W/ BLK
A37: 34 | B37: TOP ROLL | C37: ASYE23901HARDTOP | D37: #N/A
A38: 35 | B38: APPLIQUE | C38: PCPE237W28APIA70 | D38: P703 FRONT APPLIQUE RH
A39: 35 | B39: APPLIQUE | C39: PCPE237W28APIA71 | D39: P703 RH MAGNALIUM 3659APPLIQUE
A40: 35 | B40: APPLIQUE | C40: PCPE237W28APIA91 | D40: P703 FRONT APPLIQUE RH
...

Sheet Rack Guide
A1: 1:{p:"PCPE23942IN01.H-RH",d:"desc"}, | B1: =MID(A1,FIND("""",A1,1)+1,15) -> PCPE23942IN01.H | C1: PCPE23942IN01.H | D1: 1 | E1: =VLOOKUP(B1,Sheet4!$A$3:$X$2306,4,FALSE) -> INSERT RH EBONY SOHO
A2: 2:{p:"PCPE27406IN01.H-RH",d:"desc"}, | B2: =MID(A2,FIND("""",A2,1)+1,15) -> PCPE27406IN01.H | C2: PCPE27406IN01.H | D2: 2 | E2: =VLOOKUP(B2,Sheet4!$A$3:$X$2306,4,FALSE) -> P703 INSERT RH EBONY SOHO
A3: 3:{p:"PCPE23942IN02.H-RH",d:"desc"}, | B3: =MID(A3,FIND("""",A3,1)+1,15) -> PCPE23942IN02.H | C3: PCPE23942IN02.H | D3: 3 | E3: =VLOOKUP(B3,Sheet4!$A$3:$X$2306,4,FALSE) -> INSERT RH SAND SOHO
A4: 4:{p:"PCPE23942IN03.H-RH",d:"desc"}, | B4: =MID(A4,FIND("""",A4,1)+1,15) -> PCPE23942IN03.H | C4: PCPE23942IN03.H | D4: 4 | E4: =VLOOKUP(B4,Sheet4!$A$3:$X$2306,4,FALSE) -> INSERT RH EBONY SUPER SMOOTH | G4: N1WB E27406 RK3LU4 | H4: P703 DOOR REAR DBL RH | I4: 39 | J4: ARM REST | K4: PCPE27406AR03 | L4: =VLOOKUP(K4,'Rack Guide'!$C$1:$E$39,2,FALSE) -> #N/A | M4: =VLOOKUP(K4,Sheet4!$A$3:$X$2306,4,FALSE) -> #N/A
A5: 5:{p:"PCPE27406IN02.H-RH",d:"desc"}, | B5: =MID(A5,FIND("""",A5,1)+1,15) -> PCPE27406IN02.H | C5: PCPE27406IN02.H | D5: 5 | E5: =VLOOKUP(B5,Sheet4!$A$3:$X$2306,4,FALSE) -> P703 INSERT RH SAND STONE | G5: N1WB E27406 RK3LU4 | H5: P703 DOOR REAR DBL RH | I5: 33 | J5: VERTICAL INSERT | K5: ASYE27406SANDSTONE | L5: =VLOOKUP(K5,'Rack Guide'!$C$1:$E$39,2,FALSE) -> #N/A | M5: =VLOOKUP(K5,Sheet4!$A$3:$X$2306,4,FALSE) -> #N/A
A6: 6:{p:"PCPE27406IN03.H-RH",d:"desc"}, | B6: =MID(A6,FIND("""",A6,1)+1,15) -> PCPE27406IN03.H | C6: PCPE27406IN03.H | D6: 6 | E6: =VLOOKUP(B6,Sheet4!$A$3:$X$2306,4,FALSE) -> P703 INSERT RH EBONY S.SMOOTH
A7: 7:{p:"",d:""}, | B7: =MID(A7,FIND("""",A7,1)+1,18) -> ",d:""}, | C7: ",d:""}, | D7: 7 | E7: =VLOOKUP(B7,Sheet4!$A$3:$X$2306,4,FALSE) -> #N/A | G7: N1WB E23942 BF1G1E | H7: P703 DOOR FRT DBL RH | I7: 33 | J7: VERTICAL INSERT | K7: ASYE23942FEBONY | L7: =VLOOKUP(K7,'Rack Guide'!$C$1:$E$39,2,FALSE) -> #N/A | M7: =VLOOKUP(K7,Sheet4!$A$3:$X$2306,4,FALSE) -> #N/A
A8: 8:{p:"",d:""}, | B8: =MID(A8,FIND("""",A8,1)+1,18) -> ",d:""}, | C8: ",d:""}, | D8: 8 | E8: =VLOOKUP(B8,Sheet4!$A$3:$X$2306,4,FALSE) -> #N/A | G8: N1WB E23942 BF1G1E | H8: P703 DOOR FRT DBL RH | I8: 34 | J8: TOP ROLL | K8: ASY23900ASE | L8: =VLOOKUP(K8,'Rack Guide'!$C$1:$E$39,2,FALSE) -> #N/A | M8: =VLOOKUP(K8,Sheet4!$A$3:$X$2306,4,FALSE) -> #N/A
A9: 9:{p:"PCPE27406AR01.H-RH",d:"desc"}, | B9: =MID(A9,FIND("""",A9,1)+1,15)&"A" -> PCPE27406AR01.HA | C9: PCPE27406AR01.H | D9: 9 | E9: =VLOOKUP(B9,Sheet4!$A$3:$X$2306,4,FALSE) -> P703 RR DR RH EBONY NO/STITCH | G9: N1WB E23942 BF1G1E | H9: P703 DOOR FRT DBL RH | I9: 35 | J9: APPLIQUE | K9: PCPE237W28APIA91 | L9: =VLOOKUP(K9,'Rack Guide'!$C$1:$E$39,2,FALSE) -> 18 | M9: =VLOOKUP(K9,Sheet4!$A$3:$X$2306,4,FALSE) -> P703 FRONT APPLIQUE RH
A10: 10:{p:"PCPE27406AR02.H-RH",d:"desc"}, | B10: =MID(A10,FIND("""",A10,1)+1,15)&"A" -> PCPE27406AR02.HA | C10: PCPE27406AR02.H | D10: 10 | E10: =VLOOKUP(B10,Sheet4!$A$3:$X$2306,4,FALSE) -> P703 RR DR RH EBONY W/STITCH | G10: N1WB E23942 BF1G1E | H10: P703 DOOR FRT DBL RH | I10: 36 | J10: AMBIENT LIGHT | K10: PCP14E072AD00P703 | L10: =VLOOKUP(K10,'Rack Guide'!$C$1:$E$39,2,FALSE) -> #N/A | M10: =VLOOKUP(K10,Sheet4!$A$3:$X$2306,4,FALSE) -> #N/A
A11: 11:{p:"PCPE27406AR05.H-RH",d:"desc"}, | B11: =MID(A11,FIND("""",A11,1)+1,15)&"A" -> PCPE27406AR05.HA | C11: PCPE27406AR05.H | D11: 11 | E11: =VLOOKUP(B11,Sheet4!$A$3:$X$2306,4,FALSE) -> P703 REAR DR RH BLACK PACK | G11: N1WB E23942 BF1G1E | H11: P703 DOOR FRT DBL RH | I11: 37 | J11: IP EXTENSIION | K11: PCPE23942APIA20JA6 | L11: =VLOOKUP(K11,'Rack Guide'!$C$1:$E$39,2,FALSE) -> 24 | M11: =VLOOKUP(K11,Sheet4!$A$3:$X$2306,4,FALSE) -> P703 I/P EXTENSION JA6 RH
A12: 12:{p:"PCPE27406AR04.H-RH",d:"desc"}, | B12: =MID(A12,FIND("""",A12,1)+1,15)&"A" -> PCPE27406AR04.HA | C12: PCPE27406AR04.H | D12: 12 | E12: =VLOOKUP(B12,Sheet4!$A$3:$X$2306,4,FALSE) -> P703 RR DR RH S.SMOOTH | G12: N1WB E23942 BF1G1E | H12: P703 DOOR FRT DBL RH | I12: 38 | J12: LOCK SWITCH | K12: PCP14017E | L12: =VLOOKUP(K12,'Rack Guide'!$C$1:$E$39,2,FALSE) -> #N/A | M12: =VLOOKUP(K12,Sheet4!$A$3:$X$2306,4,FALSE) -> FRONT DOOR LOCK SWITCH RH
A13: 13:{p:"PCP14E072AE-RH",d:"desc"}, | B13: =MID(A13,FIND("""",A13,1)+1,10)&"F" -> PCP14E072AF | C13: PCP14E072AF | D13: 13 | E13: =VLOOKUP(B13,Sheet4!$A$3:$X$2306,4,FALSE) -> P703 AMBIENT LIGHT RH BLUE | G13: N1WB E23942 BF1G1E | H13: P703 DOOR FRT DBL RH | I13: 39 | J13: ARM REST | K13: PCPE23942AR02 | L13: =VLOOKUP(K13,'Rack Guide'!$C$1:$E$39,2,FALSE) -> #N/A | M13: =VLOOKUP(K13,Sheet4!$A$3:$X$2306,4,FALSE) -> #N/A
A14: 14:{p:"",d:""}, | B14: =MID(A14,FIND("""",A14,1)+1,18) -> ",d:""}, | C14: ",d:""}, | D14: 14 | E14: =VLOOKUP(B14,Sheet4!$A$3:$X$2306,4,FALSE) -> #N/A
A15: 15:{p:"PCP14E072AE-RH",d:"desc"}, | B15: =MID(A15,FIND("""",A15,1)+1,10)&"F" -> PCP14E072AF | C15: PCP14E072AF | D15: 15 | E15: =VLOOKUP(B15,Sheet4!$A$3:$X$2306,4,FALSE) -> P703 AMBIENT LIGHT RH BLUE | G15: N1WB E27406 SJ1G1C | H15: P703 DOOR REAR DBL RH | I15: 33 | J15: VERTICAL INSERT | K15: ASYE27406SUPERMATTE | L15: =VLOOKUP(K15,'Rack Guide'!$C$1:$E$39,2,FALSE) -> #N/A | M15: =VLOOKUP(K15,Sheet4!$A$3:$X$2306,4,FALSE) -> #N/A
A16: 16:{p:"PCP14E072EF-RH",d:"desc"}, | B16: =MID(A16,FIND("""",A16,1)+1,11) -> PCP14E072EF | C16: PCP14E072EF | D16: 16 | E16: =VLOOKUP(B16,Sheet4!$A$3:$X$2306,4,FALSE) -> P703 AMBIENT LIGHT RH ORANGE | G16: N1WB E27406 SJ1G1C | H16: P703 DOOR REAR DBL RH | I16: 39 | J16: ARM REST | K16: PCPE27406AR04 | L16: =VLOOKUP(K16,'Rack Guide'!$C$1:$E$39,2,FALSE) -> #N/A | M16: =VLOOKUP(K16,Sheet4!$A$3:$X$2306,4,FALSE) -> #N/A
A17: 17:{p:"PCPE237W28APIA70",d:"desc"}, | B17: =MID(A17,FIND("""",A17,1)+1,16) -> PCPE237W28APIA70 | C17: PCPE237W28APIA70 | D17: 17 | E17: =VLOOKUP(B17,Sheet4!$A$3:$X$2306,4,FALSE) -> P703 FRONT APPLIQUE RH
A18: 18:{p:"PCPE237W28APIA91",d:"desc"}, | B18: =MID(A18,FIND("""",A18,1)+1,16) -> PCPE237W28APIA91 | C18: PCPE237W28APIA91 | D18: 18 | E18: =VLOOKUP(B18,Sheet4!$A$3:$X$2306,4,FALSE) -> P703 FRONT APPLIQUE RH | G18: N1WB E23942 BJ1G1C | H18: P703 DOOR FRT DBL RH | I18: 33 | J18: VERTICAL INSERT | K18: PCPE23942IN01.H | L18: =VLOOKUP(K18,'Rack Guide'!$C$1:$E$39,2,FALSE) -> 1 | M18: =VLOOKUP(K18,Sheet4!$A$3:$X$2306,4,FALSE) -> INSERT RH EBONY SOHO
A19: 19:{p:"",d:""}, | B19: =MID(A19,FIND("""",A19,1)+1,18) -> ",d:""}, | C19: ",d:""}, | D19: 19 | E19: =VLOOKUP(B19,Sheet4!$A$3:$X$2306,4,FALSE) -> #N/A | G19: N1WB E23942 BJ1G1C | H19: P703 DOOR FRT DBL RH | I19: 34 | J19: TOP ROLL | K19: ASYE23900ABP | L19: =VLOOKUP(K19,'Rack Guide'!$C$1:$E$39,2,FALSE) -> #N/A | M19: =VLOOKUP(K19,Sheet4!$A$3:$X$2306,4,FALSE) -> P703 BLACK PACK VERSION.
A20: 20:{p:"PCPE23942APIA30A",d:"desc"}, | B20: =MID(A20,FIND("""",A20,1)+1,16) -> PCPE23942APIA30A | C20: PCPE23942APIA30A | D20: 20 | E20: =VLOOKUP(B20,Sheet4!$A$3:$X$2306,4,FALSE) -> FRT RH I/P EXTENSION MIC | G20: N1WB E23942 BJ1G1C | H20: P703 DOOR FRT DBL RH | I20: 35 | J20: APPLIQUE | K20: PCPE237W28APIA91 | L20: =VLOOKUP(K20,'Rack Guide'!$C$1:$E$39,2,FALSE) -> 18 | M20: =VLOOKUP(K20,Sheet4!$A$3:$X$2306,4,FALSE) -> P703 FRONT APPLIQUE RH
A21: 21:{p:"",d:""}, | B21: =MID(A21,FIND("""",A21,1)+1,18) -> ",d:""}, | C21: ",d:""}, | D21: 21 | E21: =VLOOKUP(B21,Sheet4!$A$3:$X$2306,4,FALSE) -> #N/A | G21: N1WB E23942 BJ1G1C | H21: P703 DOOR FRT DBL RH | I21: 36 | J21: AMBIENT LIGHT | K21: N1WB14E072A | L21: =VLOOKUP(K21,'Rack Guide'!$C$1:$E$39,2,FALSE) -> #N/A | M21: =VLOOKUP(K21,Sheet4!$A$3:$X$2306,4,FALSE) -> #N/A
A22: 22:{p:"PCPE23942APIA201MY-RH",d:"desc"}, | B22: =MID(A22,FIND("""",A22,1)+1,18) -> PCPE23942APIA201MY | C22: PCPE23942APIA201MY | D22: 22 | E22: =VLOOKUP(B22,Sheet4!$A$3:$X$2306,4,FALSE) -> P703 I/P EXTENSION 1MY RH | G22: N1WB E23942 BJ1G1C | H22: P703 DOOR FRT DBL RH | I22: 37 | J22: IP EXTENSIION | K22: PCPE23942APIA20JA6 | L22: =VLOOKUP(K22,'Rack Guide'!$C$1:$E$39,2,FALSE) -> 24 | M22: =VLOOKUP(K22,Sheet4!$A$3:$X$2306,4,FALSE) -> P703 I/P EXTENSION JA6 RH
A23: 23:{p:"",d:""}, | B23: =MID(A23,FIND("""",A23,1)+1,18) -> ",d:""}, | C23: ",d:""}, | D23: 23 | E23: =VLOOKUP(B23,Sheet4!$A$3:$X$2306,4,FALSE) -> #N/A | G23: N1WB E23942 BJ1G1C | H23: P703 DOOR FRT DBL RH | I23: 38 | J23: LOCK SWITCH | K23: PCP14017E | L23: =VLOOKUP(K23,'Rack Guide'!$C$1:$E$39,2,FALSE) -> #N/A | M23: =VLOOKUP(K23,Sheet4!$A$3:$X$2306,4,FALSE) -> FRONT DOOR LOCK SWITCH RH
A24: 24:{p:"PCPE23942APIA20JA6-RH",d:"desc"}, | B24: =MID(A24,FIND("""",A24,1)+1,18) -> PCPE23942APIA20JA6 | C24: PCPE23942APIA20JA6 | D24: 24 | E24: =VLOOKUP(B24,Sheet4!$A$3:$X$2306,4,FALSE) -> P703 I/P EXTENSION JA6 RH | G24: N1WB E23942 BJ1G1C | H24: P703 DOOR FRT DBL RH | I24: 39 | J24: ARM REST | K24: PCPE23942AR05.H | L24: =VLOOKUP(K24,'Rack Guide'!$C$1:$E$39,2,FALSE) -> 31 | M24: =VLOOKUP(K24,Sheet4!$A$3:$X$2306,4,FALSE) -> #N/A
A25: 25:{p:"",d:""}, | B25: =MID(A25,FIND("""",A25,1)+1,18) -> ",d:""}, | C25: ",d:""}, | D25: 25 | E25: =VLOOKUP(B25,Sheet4!$A$3:$X$2306,4,FALSE) -> #N/A
A26: 26:{p:"",d:""}, | B26: =MID(A26,FIND("""",A26,1)+1,18) -> ",d:""}, | C26: ",d:""}, | D26: 26 | E26: =VLOOKUP(B26,Sheet4!$A$3:$X$2306,4,FALSE) -> #N/A | G26: N1WB E27406 RN3LU4 | H26: P703 DOOR REAR DBL RH | I26: 39 | J26: ARM REST | K26: PCPE27406AR03.H | L26: =VLOOKUP(K26,'Rack Guide'!$C$1:$E$39,2,FALSE) -> #N/A | M26: =VLOOKUP(K26,Sheet4!$A$3:$X$2306,4,FALSE) -> #N/A
A27: 27:{p:"",d:""}, | B27: =MID(A27,FIND("""",A27,1)+1,18) -> ",d:""}, | C27: ",d:""}, | D27: 27 | E27: =VLOOKUP(B27,Sheet4!$A$3:$X$2306,4,FALSE) -> #N/A
A28: 28:{p:"PCPE23942AR01.H-RH",d:"desc"}, | B28: =MID(A28,FIND("""",A28,1)+1,15)&"A" -> PCPE23942AR01.HA | C28: PCPE23942AR01.H | D28: 28 | E28: =VLOOKUP(B28,Sheet4!$A$3:$X$2306,4,FALSE) -> P703 FRT DR RH EBONY NO-STICH | G28: N1WB E23942 HF3ZHE | H28: P703 DOOR FRT DBL RH | I28: 34 | J28: TOP ROLL | K28: ASYE23900AMIC | L28: =VLOOKUP(K28,'Rack Guide'!$C$1:$E$39,2,FALSE) -> 38 | M28: =VLOOKUP(K28,Sheet4!$A$3:$X$2306,4,FALSE) -> P703 Hard Top Roll W REINF
A29: 29:{p:"PCPE23942AR02.H-RH",d:"desc"}, | B29: =MID(A29,FIND("""",A29,1)+1,15)&"A" -> PCPE23942AR02.HA | C29: PCPE23942AR02.H | D29: 29 | E29: =VLOOKUP(B29,Sheet4!$A$3:$X$2306,4,FALSE) -> P703 FRT DR RH EBONY W/STITCH | G29: N1WB E23942 HF3ZHE | H29: P703 DOOR FRT DBL RH | I29: 37 | J29: IP EXTENSIION | K29: PCPE23942APIA30 | L29: =VLOOKUP(K29,'Rack Guide'!$C$1:$E$39,2,FALSE) -> #N/A | M29: =VLOOKUP(K29,Sheet4!$A$3:$X$2306,4,FALSE) -> #N/A
A30: 30:{p:"PCPE23942AR04.H-RH",d:"desc"}, | B30: =MID(A30,FIND("""",A30,1)+1,15)&"A" -> PCPE23942AR04.HA | C30: PCPE23942AR04.H | D30: 30 | E30: =VLOOKUP(B30,Sheet4!$A$3:$X$2306,4,FALSE) -> P703 FRT DR RH S.SMOOTH | G30: N1WB E23942 HF3ZHE | H30: P703 DOOR FRT DBL RH | I30: 38 | J30: LOCK SWITCH | K30: PCP14017E | L30: =VLOOKUP(K30,'Rack Guide'!$C$1:$E$39,2,FALSE) -> #N/A | M30: =VLOOKUP(K30,Sheet4!$A$3:$X$2306,4,FALSE) -> FRONT DOOR LOCK SWITCH RH
A31: 31:{p:"PCPE23942AR05.H-RH",d:"desc"}, | B31: =MID(A31,FIND("""",A31,1)+1,15)&"A" -> PCPE23942AR05.HA | C31: PCPE23942AR05.H | D31: 31 | E31: =VLOOKUP(B31,Sheet4!$A$3:$X$2306,4,FALSE) -> P703 FRT DR RH BLACK PACK | G31: N1WB E23942 HF3ZHE | H31: P703 DOOR FRT DBL RH | I31: 39 | J31: ARM REST | K31: PCPE23942AR01.H | L31: =VLOOKUP(K31,'Rack Guide'!$C$1:$E$39,2,FALSE) -> 28 | M31: =VLOOKUP(K31,Sheet4!$A$3:$X$2306,4,FALSE) -> #N/A
A32: 32:{p:"PCPE23942AR03.H-RH",d:"desc"}, | B32: =MID(A32,FIND("""",A32,1)+1,15)&"A" -> PCPE23942AR03.HA | C32: PCPE23942AR03.H | D32: 32 | E32: =VLOOKUP(B32,Sheet4!$A$3:$X$2306,4,FALSE) -> P703 FRT DR SAND W/STITCH
A33: 33:{p:"",d:""}, | B33: =MID(A33,FIND("""",A33,1)+1,18) -> ",d:""}, | C33: ",d:""}, | D33: 33 | E33: =VLOOKUP(B33,Sheet4!$A$3:$X$2306,4,FALSE) -> #N/A | G33: N1WB E27406 UJ1G1E | H33: P703 DOOR REAR DBL RH | I33: 39 | J33: ARM REST | K33: PCPE27406AR02 | L33: =VLOOKUP(K33,'Rack Guide'!$C$1:$E$39,2,FALSE) -> #N/A | M33: =VLOOKUP(K33,Sheet4!$A$3:$X$2306,4,FALSE) -> #N/A
A34: 34:{p:"",d:""}, | B34: =MID(A34,FIND("""",A34,1)+1,18) -> ",d:""}, | C34: ",d:""}, | D34: 34 | E34: =VLOOKUP(B34,Sheet4!$A$3:$X$2306,4,FALSE) -> #N/A
A35: 35:{p:"",d:""}, | B35: =MID(A35,FIND("""",A35,1)+1,18) -> ",d:""}, | C35: ",d:""}, | D35: 35 | E35: =VLOOKUP(B35,Sheet4!$A$3:$X$2306,4,FALSE) -> #N/A | G35: N1WB E23942 SE1G1E | H35: P703 DOOR FRT DBL RH | I35: 34 | J35: TOP ROLL | K35: ASYE23900HARDTOP | L35: =VLOOKUP(K35,'Rack Guide'!$C$1:$E$39,2,FALSE) -> #N/A | M35: =VLOOKUP(K35,Sheet4!$A$3:$X$2306,4,FALSE) -> #N/A
A36: 36:{p:"PCPE23900TOP01.H-RH",d:"PARTDESC_RACK_36"}, | B36: ASYE23900ASE | C36: ASYE23900ASE | D36: 36 | E36: =VLOOKUP(B36,Sheet4!$A$3:$X$2306,4,FALSE) -> P703 Soho Ebony W/ Urban Gray | G36: N1WB E23942 SE1G1E | H36: P703 DOOR FRT DBL RH | I36: 37 | J36: IP EXTENSIION | K36: PCPE23942APIA30 | L36: =VLOOKUP(K36,'Rack Guide'!$C$1:$E$39,2,FALSE) -> #N/A | M36: =VLOOKUP(K36,Sheet4!$A$3:$X$2306,4,FALSE) -> #N/A
A37: 37:{p:"PCPE23900TOP02.H-RH",d:"PARTDESC_RACK_37"}, | B37: ASYE23900ATS | C37: ASYE23900ATS | D37: 37 | E37: =VLOOKUP(B37,Sheet4!$A$3:$X$2306,4,FALSE) -> P703 Terra Suede Ebony W/ BLK | G37: N1WB E23942 SE1G1E | H37: P703 DOOR FRT DBL RH | I37: 38 | J37: LOCK SWITCH | K37: PCP14017E | L37: =VLOOKUP(K37,'Rack Guide'!$C$1:$E$39,2,FALSE) -> #N/A | M37: =VLOOKUP(K37,Sheet4!$A$3:$X$2306,4,FALSE) -> FRONT DOOR LOCK SWITCH RH
A38: 38:{p:"PCPE23900APIA07-RH",d:"PARTDESC_RACK_38"}, | B38: ASYE23900AMIC | C38: ASYE23900AMIC | D38: 38 | E38: =VLOOKUP(B38,Sheet4!$A$3:$X$2306,4,FALSE) -> P703 Hard Top Roll W REINF | G38: N1WB E23942 SE1G1E | H38: P703 DOOR FRT DBL RH | I38: 39 | J38: ARM REST | K38: PCPE23942AR02 | L38: =VLOOKUP(K38,'Rack Guide'!$C$1:$E$39,2,FALSE) -> #N/A | M38: =VLOOKUP(K38,Sheet4!$A$3:$X$2306,4,FALSE) -> #N/A
A39: 39:{p:"",d:""} | B39: =MID(A39,FIND("""",A39,1)+1,18) -> ",d:""} | C39: ",d:""} | D39: 39 | E39: =VLOOKUP(B39,Sheet4!$A$3:$X$2306,4,FALSE) -> #N/A

Sheet Unique PNs
A1: AttributeID | B1: AttributeDesc | C1: Value
A2: 34 | B2: TOP ROLL | C2: ASY23900ASE | D2: =VLOOKUP(C2,Sheet4!$A$3:$X$2306,4,FALSE) -> #N/A | E2: =VLOOKUP(C2,Sheet3!$C$4:$X$900,3,FALSE) -> #N/A
A3: 33 | B3: VERTICAL INSERT | C3: ASYE23864APIA9102 | D3: =VLOOKUP(C3,Sheet4!$A$3:$X$2306,4,FALSE) -> #N/A | E3: =VLOOKUP(C3,Sheet3!$C$4:$X$900,3,FALSE) -> #N/A
A4: 33 | B4: VERTICAL INSERT | C4: ASYE23864APIA9103 | D4: =VLOOKUP(C4,Sheet4!$A$3:$X$2306,4,FALSE) -> #N/A | E4: =VLOOKUP(C4,Sheet3!$C$4:$X$900,3,FALSE) -> #N/A
A5: 33 | B5: VERTICAL INSERT | C5: ASYE23865APIA91 | D5: =VLOOKUP(C5,Sheet4!$A$3:$X$2306,4,FALSE) -> #N/A | E5: =VLOOKUP(C5,Sheet3!$C$4:$X$900,3,FALSE) -> #N/A
A6: 33 | B6: VERTICAL INSERT | C6: ASYE23865APIA9102 | D6: =VLOOKUP(C6,Sheet4!$A$3:$X$2306,4,FALSE) -> #N/A | E6: =VLOOKUP(C6,Sheet3!$C$4:$X$900,3,FALSE) -> #N/A
A7: 33 | B7: VERTICAL INSERT | C7: ASYE23865APIA9103 | D7: =VLOOKUP(C7,Sheet4!$A$3:$X$2306,4,FALSE) -> #N/A | E7: =VLOOKUP(C7,Sheet3!$C$4:$X$900,3,FALSE) -> #N/A
A8: 34 | B8: TOP ROLL | C8: ASYE23900ABP | D8: =VLOOKUP(C8,Sheet4!$A$3:$X$2306,4,FALSE) -> P703 BLACK PACK VERSION. | E8: =VLOOKUP(C8,Sheet3!$C$4:$X$900,3,FALSE) -> P703 BLACK PACK VERSION.
A9: 34 | B9: TOP ROLL | C9: ASYE23900AMIC | D9: =VLOOKUP(C9,Sheet4!$A$3:$X$2306,4,FALSE) -> P703 Hard Top Roll W REINF | E9: =VLOOKUP(C9,Sheet3!$C$4:$X$900,3,FALSE) -> P703 Hard Top Roll W REINF
A10: 34 | B10: TOP ROLL | C10: ASYE23900ASE | D10: =VLOOKUP(C10,Sheet4!$A$3:$X$2306,4,FALSE) -> P703 Soho Ebony W/ Urban Gray | E10: =VLOOKUP(C10,Sheet3!$C$4:$X$900,3,FALSE) -> P703 Soho Ebony W/ Urban Gray
A11: 34 | B11: TOP ROLL | C11: ASYE23900ATS | D11: =VLOOKUP(C11,Sheet4!$A$3:$X$2306,4,FALSE) -> P703 Terra Suede Ebony W/ BLK | E11: =VLOOKUP(C11,Sheet3!$C$4:$X$900,3,FALSE) -> P703 Terra Suede Ebony W/ BLK
A12: 34 | B12: TOP ROLL | C12: ASYE23900HARDTOP | D12: =VLOOKUP(C12,Sheet4!$A$3:$X$2306,4,FALSE) -> #N/A | E12: =VLOOKUP(C12,Sheet3!$C$4:$X$900,3,FALSE) -> #N/A
A13: 34 | B13: TOP ROLL | C13: ASYE23901ABP | D13: =VLOOKUP(C13,Sheet4!$A$3:$X$2306,4,FALSE) -> P703 BLACK PACK VERSION | E13: =VLOOKUP(C13,Sheet3!$C$4:$X$900,3,FALSE) -> P703 BLACK PACK VERSION
... A112: 33 | B112: VERTICAL INSERT | C112: PCPE27407IN03.H | D112: =VLOOKUP(C112,Sheet4!$A$3:$X$2306,4,FALSE) -> P703 INSERT LH EBONY S.SMOOTH | E112: =VLOOKUP(C112,Sheet3!$C$4:$X$900,3,FALSE) -> #N/A

Sheet Sheet3
A1: Production Schedule - Weekly w/Days On Hand - FDDAT
A3: Mar 6, 2026 6:02:44 AM
A4: Prod Dept | B4: Prod Resc | C4: PN TRIM | D4: Part Number | E4: Part Description 1 | F4: Major Group | G4: Minor Group | H4: Std Rate | I4: Qty On Hand | J4: Past Entries | K4: 46087 | L4: 46094 | M4: 46101 | N4: 46108 | O4: 46115 | P4: 46122 | Q4: 46129 | R4: 46136 | S4: 46143 | T4: 46150 | U4: 46157 | V4: 46164 | W4: 46171 | X4: 46178 | Y4: 46185 | Z4: 46192 | AA4: 46199 | AB4: 46206 | AC4: 46213 | AD4: 46220
A5: DFTAS | B5: 70301 | C5: =TRIM(D5) -> N1WB E03512 DE31NB | D5: N1WB E03512 DE31NB | E5: P703 A PLR UPR NONBRANDED RH | F5: 703 | G5: PLA | H5: 73.4694 | I5: 992 | J5: 0 | K5: 328 | L5: 964 | M5: 674 | N5: 898 | O5: 1134 | P5: 990 | Q5: 594 | R5: 752 | S5: 1041 | T5: 1056 | U5: 896 | V5: 978 | W5: 1478 | X5: 1360 | Y5: 1518 | Z5: 1266 | AA5: 0 | AB5: 582 | AC5: 1478 | AD5: 1466
A6: DFTAS | B6: 70301 | C6: =TRIM(D6) -> N1WB E03512 EE31NB | D6: N1WB E03512 EE31NB | E6: P703 A PILLAR UPR BRANDED RH | F6: 703 | G6: PLA | H6: 73.4694 | I6: 207 | J6: 0 | K6: 60 | L6: 212 | M6: 146 | N6: 118 | O6: 224 | P6: 212 | Q6: 132 | R6: 184 | S6: 238 | T6: 224 | U6: 238 | V6: 250 | W6: 330 | X6: 330 | Y6: 410 | Z6: 322 | AA6: 0 | AB6: 132 | AC6: 330 | AD6: 330
A7: DFTAS | B7: 70301 | C7: =TRIM(D7) -> N1WB E03512 EE3ZHE | D7: N1WB E03512 EE3ZHE | E7: P703 A PILLAR UPR BRANDED RH | F7: 703 | G7: PLA | H7: 73.4694 | I7: 587 | J7: 0 | K7: 0 | L7: 0 | M7: 75 | N7: 132 | O7: 106 | P7: 144 | Q7: 264 | R7: 238 | S7: 238 | T7: 264 | U7: 212 | V7: 184 | W7: 264 | X7: 238 | Y7: 304 | Z7: 292 | AA7: 0 | AB7: 106 | AC7: 264 | AD7: 238
A8: DFTAS | B8: 70301 | C8: =TRIM(D8) -> N1WB E03512 EEW-01 | D8: N1WB E03512 EEW-01 | E8: P703 A PILLAR UPR BRANDED RH | F8: 703 | G8: PLA | H8: 73.4694 | J8: 3 | K8: 0 | L8: 0 | M8: 0 | N8: 0 | O8: 0 | P8: 0 | Q8: 0 | R8: 0 | S8: 0 | T8: 0 | U8: 0 | V8: 0 | W8: 0 | X8: 0 | Y8: 0 | Z8: 0 | AA8: 0 | AB8: 0 | AC8: 0 | AD8: 0
A9: DFTAS | B9: 70301 | C9: =TRIM(D9) -> N1WB E03513 DG31NB | D9: N1WB E03513 DG31NB | E9: P703 A PLR UPR NONBRANDED LH | F9: 703 | G9: PLA | H9: 73.4694 | I9: 61 | J9: 0 | K9: 328 | L9: 964 | M9: 674 | N9: 898 | O9: 1134 | P9: 990 | Q9: 594 | R9: 752 | S9: 1041 | T9: 1056 | U9: 896 | V9: 978 | W9: 1478 | X9: 1360 | Y9: 1518 | Z9: 1266 | AA9: 0 | AB9: 582 | AC9: 1478 | AD9: 1466
A10: DFTAS | B10: 70301 | C10: =TRIM(D10) -> N1WB E03513 DH31NB | D10: N1WB E03513 DH31NB | E10: P703 A PLR UPR NONBRANDED LH | F10: 703 | G10: PLA | H10: 73.4694 | I10: 704 | J10: 0 | K10: 550 | L10: 924 | M10: 701 | N10: 884 | O10: 1148 | P10: 976 | Q10: 623 | R10: 712 | S10: 1044 | T10: 1096 | U10: 896 | V10: 993 | W10: 1452 | X10: 1346 | Y10: 1558 | Z10: 1281 | AA10: 0 | AB10: 582 | AC10: 1478 | AD10: 1438
A11: DFTAS | B11: 70301 | C11: =TRIM(D11) -> N1WB E03513 EG31NB | D11: N1WB E03513 EG31NB | E11: P703 A PILLAR UPR BRANDED LH | F11: 703 | G11: PLA | H11: 73.4694 | I11: 40 | J11: 0 | K11: 60 | L11: 212 | M11: 146 | N11: 118 | O11: 224 | P11: 212 | Q11: 132 | R11: 184 | S11: 238 | T11: 224 | U11: 238 | V11: 250 | W11: 330 | X11: 330 | Y11: 410 | Z11: 322 | AA11: 0 | AB11: 132 | AC11: 330 | AD11: 330
A12: DFTAS | B12: 70301 | C12: =TRIM(D12) -> N1WB E03513 EG3ZHE | D12: N1WB E03513 EG3ZHE | E12: P703 A PILLAR UPR BRANDED LH | F12: 703 | G12: PLA | H12: 73.4694 | J12: 0 | K12: 0 | L12: 0 | M12: 75 | N12: 132 | O12: 106 | P12: 144 | Q12: 264 | R12: 238 | S12: 238 | T12: 264 | U12: 212 | V12: 184 | W12: 264 | X12: 238 | Y12: 304 | Z12: 292 | AA12: 0 | AB12: 106 | AC12: 264 | AD12: 238
A13: DFTAS | B13: 70301 | C13: =TRIM(D13) -> N1WB E03513 EH31NB | D13: N1WB E03513 EH31NB | E13: P703 A PILLAR UPR BRANDED LH | F13: 703 | G13: PLA | H13: 73.4694 | I13: 254 | J13: 0 | K13: 13 | L13: 212 | M13: 172 | N13: 132 | O13: 192 | P13: 238 | Q13: 172 | R13: 158 | S13: 231 | T13: 264 | U13: 212 | V13: 247 | W13: 368 | X13: 330 | Y13: 384 | Z13: 285 | AA13: 0 | AB13: 160 | AC13: 368 | AD13: 330
A14: DFTAS | B14: 70301 | C14: =TRIM(D14) -> N1WB E03513 EH3ZHE | D14: N1WB E03513 EH3ZHE | E14: P703 A PILLAR UPR BRANDED LH | F14: 703 | G14: PLA | H14: 73.4694 | I14: 388 | J14: 0 | K14: 0 | L14: 128 | M14: 132 | N14: 136 | O14: 106 | P14: 144 | Q14: 264 | R14: 243 | S14: 224 | T14: 264 | U14: 212 | V14: 189 | W14: 238 | X14: 224 | Y14: 344 | Z14: 280 | AA14: 0 | AB14: 106 | AC14: 238 | AD14: 224
A15: DFTAS | B15: 70301 | C15: =TRIM(D15) -> N1WB E03513 EHW-01 | D15: N1WB E03513 EHW-01 | E15: P703 A PILLAR UPR BRANDED LH | F15: 703 | G15: PLA | H15: 73.4694 | J15: 3 | K15: 0 | L15: 0 | M15: 0 | N15: 0 | O15: 0 | P15: 0 | Q15: 0 | R15: 0 | S15: 0 | T15: 0 | U15: 0 | V15: 0 | W15: 0 | X15: 0 | Y15: 0 | Z15: 0 | AA15: 0 | AB15: 0 | AC15: 0 | AD15: 0
A16: DFTAS | B16: 70302 | C16: =TRIM(D16) -> N1WB E13201 DA3ZHE | D16: N1WB E13201 DA3ZHE | E16: P703 PLT ASY FRT DR SCF | F16: 703 | G16: PLA | H16: 71.2871 | I16: 317 | J16: 43 | K16: 1584 | L16: 1362 | M16: 1000 | N16: 1160 | O16: 1432 | P16: 1368 | Q16: 986 | R16: 1132 | S16: 1518 | T16: 1570 | U16: 1318 | V16: 1404 | W16: 2066 | X16: 1930 | Y16: 2254 | Z16: 1860 | AA16: 0 | AB16: 822 | AC16: 2066 | AD16: 2016
A17: DFTAS | B17: 70302 | C17: =TRIM(D17) -> N1WB E243A53 ED3ZHE | D17: N1WB E243A53 ED3ZHE | E17: P703 PNL ASY CTR BDY PLR LH | F17: 703 | G17: PLA | H17: 66.6666 | I17: 488 | J17: 0 | K17: 1510 | L17: 1210 | M17: 998 | N17: 1170 | O17: 1432 | P17: 1368 | Q17: 994 | R17: 1144 | S17: 1502 | T17: 1572 | U17: 1332 | V17: 1394 | W17: 2058 | X17: 1934 | Y17: 2268 | Z17: 1856 | AA17: 0 | AB17: 828 | AC17: 2070 | AD17: 2014
A18: DFTAS | B18: 70302 | C18: =TRIM(D18) -> N1WB E31007 EB3ZHE | D18: N1WB E31007 EB3ZHE | E18: P703 PNL BDY SD RR CNR TR | F18: 703 | G18: PLA | H18: 85.7142 | I18: 105 | J18: 203 | K18: 1584 | L18: 1360 | M18: 1004 | N18: 1160 | O18: 1436 | P18: 1376 | Q18: 990 | R18: 1136 | S18: 1496 | T18: 1570 | U18: 1338 | V18: 1400 | W18: 2054 | X18: 1928 | Y18: 2260 | Z18: 1852 | AA18: 0 | AB18: 828 | AC18: 2076 | AD18: 2020
A19: DFTAS | B19: 70303 | C19: =TRIM(D19) -> N1WB 17D568 EF3JA6 | D19: N1WB 17D568 EF3JA6 | E19: P703 RAIN SENSOR COVER | F19: 703 | G19: PLA | H19: 83.7209 | I19: 618 | J19: 0 | K19: 1497 | L19: 1335 | M19: 969 | N19: 1220 | O19: 1334 | P19: 1478 | Q19: 1075 | R19: 1066 | S19: 1573 | T19: 1545 | U19: 1469 | V19: 1300 | W19: 2074 | X19: 2025 | Y19: 1901 | Z19: 2310 | AA19: 58 | AB19: 643 | AC19: 2074 | AD19: 2073
A20: DFTAS | B20: 70303 | C20: =TRIM(D20) -> N1WB 17D568 EFW-01 | D20: N1WB 17D568 EFW-01 | E20: P703 RAIN SENSOR COVER | F20: 703 | G20: PLA | H20: 83.7209 | J20: 3 | K20: 0 | L20: 0 | M20: 0 | N20: 0 | O20: 0 | P20: 0 | Q20: 0 | R20: 0 | S20: 0 | T20: 0 | U20: 0 | V20: 0 | W20: 0 | X20: 0 | Y20: 0 | Z20: 0 | AA20: 0 | AB20: 0 | AC20: 0 | AD20: 0
A21: DFTAS | B21: 70304 | C21: =TRIM(D21) -> ASYE025B85B | D21: ASYE025B85B | E21: P703 TWTR CVR BRANDED ASSY LH | F21: 703 | G21: PLA | H21: 87.8048 | I21: 205 | J21: 0 | K21: 0 | L21: 0 | M21: 130 | N21: 268 | O21: 212 | P21: 288 | Q21: 528 | R21: 481 | S21: 462 | T21: 528 | U21: 424 | V21: 373 | W21: 502 | X21: 462 | Y21: 648 | Z21: 572 | AA21: 0 | AB21: 212 | AC21: 502 | AD21: 462
A22: DFTAS | B22: 70304 | C22: =TRIM(D22) -> ASYE025B85B1NB | D22: ASYE025B85B1NB | E22: P703 TWTR CVR BRANDED ASSY LH | F22: 703 | G22: PLA | H22: 87.8048 | I22: -483 | J22: 483 | K22: 73 | L22: 424 | M22: 318 | N22: 250 | O22: 416 | P22: 450 | Q22: 304 | R22: 342 | S22: 469 | T22: 488 | U22: 450 | V22: 497 | W22: 698 | X22: 660 | Y22: 794 | Z22: 607 | AA22: 0 | AB22: 292 | AC22: 698 | AD22: 660
A23: DFTAS | B23: 70306 | C23: =TRIM(D23) -> N1WB E41018 CD | D23: N1WB E41018 CD | E23: P703 TAILGATE ASSY | F23: 703 | G23: PLA | H23: 160 | I23: 183 | J23: 0 | K23: 0 | L23: 0 | M23: 0 | N23: 0 | O23: 0 | P23: 0 | Q23: 0 | R23: 0 | S23: 189 | T23: 0 | U23: 0 | V23: 0 | W23: 0 | X23: 0 | Y23: 0 | Z23: 202 | AA23: 0 | AB23: 0 | AC23: 0 | AD23: 0
A24: DFTAS | B24: 70306 | C24: =TRIM(D24) -> R1WB E41018 CA | D24: R1WB E41018 CA | E24: P703 TAILGATE ASSY | F24: 703 | G24: PLA | H24: 66.6666 | I24: 1674 | J24: 0 | K24: 126 | L24: 1380 | M24: 960 | N24: 1220 | O24: 1340 | P24: 1420 | Q24: 1060 | R24: 1020 | S24: 1530 | T24: 1600 | U24: 1480 | V24: 1237 | W24: 2080 | X24: 1940 | Y24: 1920 | Z24: 2259 | AA24: 60 | AB24: 660 | AC24: 2100 | AD24: 2060
A25: DFTAS | B25: 70308 | C25: =TRIM(D25) -> KTN1WB 16L559 DB | D25: KTN1WB 16L559 DB | E25: P703 REAR SPLA SHIELDS | F25: 703 | G25: PLA | H25: 80 | I25: 970 | J25: 0 | K25: 710 | L25: 1346 | M25: 928 | N25: 1264 | O25: 1344 | P25: 1072 | Q25: 768 | R25: 1456 | S25: 1152 | T25: 1168 | U25: 1248 | V25: 1536 | W25: 1488 | X25: 1392 | Y25: 1680 | Z25: 1008 | AA25: 0 | AB25: 736 | AC25: 1840 | AD25: 1776
A26: DFTAS | B26: 70308 | C26: =TRIM(D26) -> KTN1WB 16L559 FB | D26: KTN1WB 16L559 FB | E26: P703 REAR SPLA SHIELDS | F26: 703 | G26: PLA | H26: 80 | I26: 888 | J26: 0 | K26: 0 | L26: 0 | M26: 0 | N26: 0 | O26: 100 | P26: 192 | Q26: 160 | R26: 368 | S26: 224 | T26: 176 | U26: 256 | V26: 192 | W26: 208 | X26: 224 | Y26: 320 | Z26: 192 | AA26: 0 | AB26: 96 | AC26: 240 | AD26: 240
A27: DFTAS | B27: 70309 | C27: =TRIM(D27) -> N1WB 17C790 GA | D27: N1WB 17C790 GA | E27: P703 REDBACK SUPT BRKT RH | F27: 703 | G27: PLA | H27: 116.129 | I27: -4 | J27: 4 | K27: 540 | L27: 0 | M27: 108 | N27: 432 | O27: 0 | P27: 0 | Q27: 108 | R27: 432 | S27: 108 | T27: 432 | U27: 108 | V27: 436 | W27: 0 | X27: 108 | Y27: 540 | Z27: 432 | AA27: 0 | AB27: 0 | AC27: 108 | AD27: 432
A28: DFTAS | B28: 70309 | C28: =TRIM(D28) -> N1WB 17D698 AD3ZHE | D28: N1WB 17D698 AD3ZHE | E28: P703 CVR ASY RV O/S MIR MTG HL | F28: 703 | G28: PLA | H28: 90 | I28: -18 | J28: 18 | K28: 1728 | L28: 1253 | M28: 951 | N28: 1296 | O28: 1296 | P28: 1252 | Q28: 1080 | R28: 1167 | S28: 1512 | T28: 1512 | U28: 1469 | V28: 1425 | W28: 1987 | X28: 2074 | Y28: 1858 | Z28: 1904 | AA28: 130 | AB28: 950 | AC28: 2117 | AD28: 1944
A29: DFTAS | B29: 70310 | C29: =TRIM(D29) -> N1WB 17C791 GA | D29: N1WB 17C791 GA | E29: P703 REDBACK SUPT BRKT LH | F29: 703 | G29: PLA | H29: 116.129 | I29: 577 | J29: 0 | K29: 0 | L29: 395 | M29: 108 | N29: 0 | O29: 0 | P29: 432 | Q29: 108 | R29: 432 | S29: 108 | T29: 0 | U29: 432 | V29: 115 | W29: 432 | X29: 108 | Y29: 432 | Z29: 108 | AA29: 0 | AB29: 0 | AC29: 432 | AD29: 108
A30: DFTAS | B30: 70310 | C30: =TRIM(D30) -> N1WB 17D699 AD3ZHE | D30: N1WB 17D699 AD3ZHE | E30: P703 CVR ASY RV O/S MIR MTG HL | F30: 703 | G30: PLA | H30: 90 | I30: 304 | J30: 0 | K30: 1208 | L30: 1253 | M30: 951 | N30: 1296 | O30: 1296 | P30: 1252 | Q30: 1080 | R30: 1167 | S30: 1512 | T30: 1512 | U30: 1469 | V30: 1425 | W30: 1987 | X30: 2074 | Y30: 1858 | Z30: 1900 | AA30: 130 | AB30: 950 | AC30: 2117 | AD30: 1944
A31: DFTAS | B31: 70313 | C31: =TRIM(D31) -> ASYE23901ABP | D31: ASYE23901ABP | E31: P703 BLACK PACK VERSION | F31: 703 | G31: PLA | H31: 80 | I31: 54 | J31: 0 | K31: 126 | L31: 93 | M31: 86 | N31: 79 | O31: 94 | P31: 75 | Q31: 67 | R31: 86 | S31: 111 | T31: 111 | U31: 80 | V31: 132 | W31: 139 | X31: 140 | Y31: 206 | Z31: 46 | AA31: 0 | AB31: 104 | AC31: 134 | AD31: 128
A32: DFTAS | B32: 70313 | C32: =TRIM(D32) -> ASYE23901ADSG | D32: ASYE23901ADSG | E32: P703 Dark Space Grey TopRollLH | F32: 703 | G32: PLA | H32: 80 | J32: 0 | K32: 0 | L32: 0 | M32: 0 | N32: 0 | O32: 0 | P32: 0 | Q32: 0 | R32: 0 | S32: 2 | T32: 0 | U32: 0 | V32: 10 | W32: 0 | X32: 0 | Y32: 0 | Z32: 0 | AA32: 0 | AB32: 0 | AC32: 0 | AD32: 0
A33: DFTAS | B33: 70313 | C33: =TRIM(D33) -> ASYE23901AMIC | D33: ASYE23901AMIC | E33: P703 Hard Top Roll W REINF | F33: 703 | G33: PLA | H33: 80 | I33: 178 | J33: 0 | K33: 1153 | L33: 682 | M33: 811 | N33: 1019 | O33: 1153 | P33: 762 | Q33: 575 | R33: 915 | S33: 1062 | T33: 1085 | U33: 767 | V33: 1296 | W33: 1480 | X33: 1220 | Y33: 1921 | Z33: 420 | AA33: 0 | AB33: 1176 | AC33: 1503 | AD33: 1396
A34: DFTAS | B34: 70313 | C34: =TRIM(D34) -> ASYE23901ASE | D34: ASYE23901ASE | E34: P703 Soho Ebony W/ Urban Gray | F34: 703 | G34: PLA | H34: 80 | I34: 47 | J34: 0 | K34: 116 | L34: 88 | M34: 56 | N34: 72 | O34: 144 | P34: 110 | Q34: 56 | R34: 128 | S34: 144 | T34: 132 | U34: 116 | V34: 207 | W34: 196 | X34: 185 | Y34: 263 | Z34: 54 | AA34: 0 | AB34: 196 | AC34: 216 | AD34: 180
A35: DFTAS | B35: 70313 | C35: =TRIM(D35) -> ASYE23901ATS | D35: ASYE23901ATS | E35: P703 Terra Suede Ebony W/ BLK | F35: 703 | G35: PLA | H35: 80 | I35: 43 | J35: 0 | K35: 164 | L35: 152 | M35: 154 | N35: 106 | O35: 87 | P35: 219 | Q35: 244 | R35: 247 | S35: 250 | T35: 243 | U35: 170 | V35: 247 | W35: 247 | X35: 261 | Y35: 396 | Z35: 88 | AA35: 0 | AB35: 192 | AC35: 240 | AD35: 240
A36: DFTAS | B36: 70314 | C36: =TRIM(D36) -> N1WB 14A563 KD3ZHE | D36: N1WB 14A563 KD3ZHE | E36: P703 HSG ASY-WDO REG FRT RH SW | F36: 703 | G36: PLA | H36: 30 | I36: 2167 | J36: 0 | K36: 137 | L36: 1152 | M36: 1038 | N36: 1228 | O36: 1344 | P36: 1268 | Q36: 1074 | R36: 1192 | S36: 1536 | T36: 1536 | U36: 1382 | V36: 1536 | W36: 2112 | X36: 1958 | Y36: 1958 | Z36: 1382 | AA36: 308 | AB36: 1306 | AC36: 2112 | AD36: 1958
A37: DFTAS | B37: 70315 | C37: =TRIM(D37) -> N1WB 14A567 BE3ZHE | D37: N1WB 14A567 BE3ZHE | E37: P703 HSG ASY-WDO REG RH SW RR | F37: 703 | G37: PLA | H37: 80 | I37: 1968 | J37: 0 | K37: 151 | L37: 1152 | M37: 1114 | N37: 1344 | O37: 1344 | P37: 1190 | Q37: 1038 | R37: 1228 | S37: 1498 | T37: 1574 | U37: 1344 | V37: 1581 | W37: 1998 | X37: 1958 | Y37: 2036 | Z37: 1496 | AA37: 232 | AB37: 1190 | AC37: 2112 | AD37: 2034
A38: DFTAS | B38: 70325 | C38: =TRIM(D38) -> N1WB E13200 DA3ZHE | D38: N1WB E13200 DA3ZHE | E38: P703 PLT ASY FRT DR SCF | F38: 703 | G38: PLA | H38: 71.2871 | I38: 383 | J38: 0 | K38: 1529 | L38: 1326 | M38: 1000 | N38: 1160 | O38: 1446 | P38: 1378 | Q38: 980 | R38: 1152 | S38: 1504 | T38: 1562 | U38: 1340 | V38: 1406 | W38: 2052 | X38: 1922 | Y38: 2260 | Z38: 1838 | AA38: 0 | AB38: 836 | AC38: 2088 | AD38: 2016
A39: DFTAS | B39: 70325 | C39: =TRIM(D39) -> N1WB E243A52 ED3ZHE | D39: N1WB E243A52 ED3ZHE | E39: P703 PNL ASY CTR BDY PLR RH | F39: 703 | G39: PLA | H39: 66.6666 | I39: 524 | J39: 0 | K39: 1438 | L39: 1354 | M39: 998 | N39: 1170 | O39: 1440 | P39: 1372 | Q39: 982 | R39: 1134 | S39: 1508 | T39: 1578 | U39: 1320 | V39: 1400 | W39: 2070 | X39: 1926 | Y39: 2258 | Z39: 1846 | AA39: 0 | AB39: 828 | AC39: 2078 | AD39: 2016
A40: DFTAS | B40: 70325 | C40: =TRIM(D40) -> N1WB E31006 EB3ZHE | D40: N1WB E31006 EB3ZHE | E40: P703 PNL BDY SD RR CNR TR | F40: 703 | G40: PLA | H40: 85.7142 | I40: 224 | J40: 304 | K40: 1584 | L40: 1370 | M40: 990 | N40: 1170 | O40: 1438 | P40: 1364 | Q40: 990 | R40: 1137 | S40: 1504 | T40: 1576 | U40: 1324 | V40: 1400 | W40: 2062 | X40: 1932 | Y40: 2248 | Z40: 1848 | AA40: 0 | AB40: 828 | AC40: 2076 | AD40: 2020
A41: DFTAS | B41: 70326 | C41: =TRIM(D41) -> N1WB E291A35 MAE | D41: N1WB E291A35 MAE | E41: P703 BOX TOPS LH | F41: 703 | G41: PLA | H41: 81.8182 | J41: 0 | K41: 90 | L41: 0 | M41: 0 | N41: 0 | O41: 0 | P41: 0 | Q41: 83 | R41: 0 | S41: 76 | T41: 0 | U41: 0 | V41: 0 | W41: 0 | X41: 0 | Y41: 0 | Z41: 111 | AA41: 0 | AB41: 0 | AC41: 0 | AD41: 0
...

Sheet Sheet4
B1: Inventory QOH w/Days OH (excluding MRO) - FDDAT
B2: MRP Demand Days: 90
A3: Part Number | B3: Part Number | C3: Part CstVnd Part Number | D3: Part Description 1 | E3: Part Description 2 | F3: Part Description 3 | G3: PP Status | H3: Part CstVnd Code | I3: Vendor Name | J3: Part Major Group | K3: Part Minor Group | L3: Part CCC | M3: Part GL Exp Code | N3: Part Type | O3: Plant Code | P3: Qty On Hand | Q3: UoM | R3: Days On Hand | S3: MRP Demand Qty | T3: Act Avg Daily Demand | U3: Est Daily Demand | V3: Days On Hand (Act/Est) | W3: Run Out Date w weekend days | X3: Run Out Date skip weekend
A4: =TRIM(B4) -> 68566341AB | B4: 68566341AB | C4: 68566341AB | D4: DT MCA CENTER BRACKET | F4: 37977 | G4: A | J4: DT | K4: PLA | M4: FGP | N4: Mfg | O4: DFT | P4: 1779 | Q4: EA | R4: 1.4639566 | S4: 78120 | T4: 1215.2 | U4: 0 | V4: 1.4639566 | W4: 46088 | X4: 46090
A5: =TRIM(B5) -> 68618402AA | B5: 68618402AA | C5: 68618402AA | D5: WS TOW HOOK BOOT AERO PRE RH | E5: SB43/180 | F5: 43184 | G5: A | H5: XFNGFY | J5: WS | K5: PLA | M5: FGP | N5: Mfg | O5: DFT | P5: 150 | Q5: EA | R5: 1.6233766 | S5: 5940 | T5: 92.4 | U5: 0 | V5: 1.6233766 | W5: 46088 | X5: 46090
A6: =TRIM(B6) -> 85824848 | B6: 85824848 | C6: 85824848 | D6: BT1CC A-PILLAR UP LEVEL RH | E6: 216 | F6: 36802 | G6: A | H6: GMC01010 | J6: GM | K6: PLA | M6: FGP | N6: Mfg | O6: DFT | P6: 17 | Q6: EA | R6: 1.3575865 | S6: 805 | T6: 12.522222 | U6: 0 | V6: 1.3575865 | W6: 46088 | X6: 46090
A7: =TRIM(B7) -> 85861637 | B7: 85861637 | C7: 85861637 | D7: BT1CC BRKT-AIRBAG SI IMP SEN | G7: A | J7: GM | K7: MTL | M7: FGP | N7: Mfg | O7: DFT | P7: 360 | Q7: EA | R7: 3.2142857 | S7: 7200 | T7: 112 | U7: 0 | V7: 3.2142857 | W7: 46090 | X7: 46090
A8: =TRIM(B8) -> ASYCS14A18OS | B8: ASYCS14A18OS | C8: M2DB-S444A18-AA | D8: U725 BRKT STRUT TL GT | F8: MB2/1000 ROW 99 | G8: A | J8: BRN | K8: MTL | M8: WIP | N8: Mfg | O8: DFT | P8: 1377 | Q8: EA | R8: 1.9602168 | S8: 45159 | T8: 702.47333 | U8: 0 | V8: 1.9602168 | W8: 46088 | X8: 46090
A9: =TRIM(B9) -> ASYE025B85B | B9: ASYE025B85B | C9: N1WB-E03513-EAW | D9: P703 TWTR CVR BRANDED ASSY LH | G9: A | H9: FRD01020 | J9: 703 | K9: PLA | M9: WIP | N9: Mfg | O9: DFT | P9: 205 | Q9: EA | R9: 3.0590927 | S9: 4308 | T9: 67.013333 | U9: 0 | V9: 3.0590927 | W9: 46090 | X9: 46090
A10: =TRIM(B10) -> ASYE23900ABP | B10: ASYE23900ABP | C10: N1WB E23942 | D10: P703 BLACK PACK VERSION. | F10: ROW XXXX | G10: A | J10: 703 | K10: PLA | M10: WIP | N10: Mfg | O10: DFT | P10: 31 | Q10: EA | R10: 1.5866697 | S10: 1256 | T10: 19.537778 | U10: 0 | V10: 1.5866697 | W10: 46088 | X10: 46090
A11: =TRIM(B11) -> ASYE23900ASE | B11: ASYE23900ASE | C11: N1WB-E23942-BAW | D11: P703 Soho Ebony W/ Urban Gray | E11: Stitch N1WB-E23900-A-PIA-03 | F11: ROW XXXX | G11: A | J11: 703 | K11: PLA | M11: WIP | N11: Mfg | O11: DFT | P11: 26 | Q11: EA | R11: 1.0960187 | S11: 1525 | T11: 23.722222 | U11: 0 | V11: 1.0960187 | W11: 46088 | X11: 46090
A12: =TRIM(B12) -> ASYE23901ABP | B12: ASYE23901ABP | C12: N1WB-E23943 | D12: P703 BLACK PACK VERSION | E12: Stitch | F12: ROW XXXX | G12: A | J12: 703 | K12: PLA | M12: WIP | N12: Mfg | O12: DFT | P12: 54 | Q12: EA | R12: 2.7638763 | S12: 1256 | T12: 19.537778 | U12: 0 | V12: 2.7638763 | W12: 46089 | X12: 46090
A13: =TRIM(B13) -> ASYE23901ASE | B13: ASYE23901ASE | C13: N1WB-E23943-KAW | D13: P703 Soho Ebony W/ Urban Gray | E13: Stitch N1WB-E23901-A-PIA-03 | F13: ROW XXXX | G13: A | J13: 703 | K13: PLA | M13: WIP | N13: Mfg | O13: DFT | P13: 47 | Q13: EA | R13: 1.9696405 | S13: 1534 | T13: 23.862222 | U13: 0 | V13: 1.9696405 | W13: 46088 | X13: 46090
A14: =TRIM(B14) -> ASYE23901ATS | B14: ASYE23901ATS | C14: N1WB-E23943-YAW/ZAW | D14: P703 Terra Suede Ebony W/ BLK | E14: Stitch L N1WB-E23901-A-PIA-03 | F14: ROW XXXX | G14: A | J14: 703 | K14: PLA | M14: WIP | N14: Mfg | O14: DFT | P14: 43 | Q14: EA | R14: 1.0701842 | S14: 2583 | T14: 40.18 | U14: 0 | V14: 1.0701842 | W14: 46088 | X14: 46090
A15: =TRIM(B15) -> ASYHS111K35W20 | B15: ASYHS111K35W20 | C15: MB3B-58111K48-CB | D15: U725/P703 K35-W20 NUT WELD ASY | E15: DET58111K35 | F15: ROW 268 MB4/1200 | G15: A | H15: FRD01012 | J15: BRN | K15: MTL | M15: WIP | N15: Mfg | O15: DFT | P15: 3417 | Q15: EA | R15: 3.6013491 | S15: 60995 | T15: 948.81111 | U15: 0 | V15: 3.6013491 | W15: 46090 | X15: 46090
A16: =TRIM(B16) -> ASYHS20777W14P703 | B16: ASYHS20777W14P703 | C16: MB3B 5810693 AA | D16: P703 NUT WELD SUB ASSY | E16: PUR 5810777 AC | F16: ROW419-W14 | G16: A | H16: FRD01012 | J16: 703 | K16: MTL | M16: WIP | N16: Mfg | O16: DFT | P16: 1951 | Q16: EA | R16: 2.03385 | S16: 61667 | T16: 959.26444 | U16: 0 | V16: 2.03385 | W16: 46089 | X16: 46090
A17: =TRIM(B17) -> ASYHS24B02W21W22 | B17: ASYHS24B02W21W22 | C17: P1WB E280A54_55 A | D17: P703 HS2-4B02-W21-W22 NUT WLD | F17: ROW303F-303G-W21-W22-MB2 | G17: A | H17: FRD01012 | J17: 703 | K17: MTL | M17: WIP | N17: Mfg | O17: DFT | P17: 1669 | Q17: EA | R17: 2.8261737 | S17: 37964 | T17: 590.55111 | U17: 0 | V17: 2.8261737 | W17: 46089 | X17: 46090
A18: =TRIM(B18) -> ASYHS25A65W2 | B18: ASYHS25A65W2 | C18: KB3B 2610020 A | D18: HS2-5A65-W2 NUT WELD SUB ASSY | E18: KB3B 26625A65 A | F18: ROW395-W2-MB4 | G18: A | H18: FRD01012 | J18: 703 | K18: MTL | M18: WIP | N18: Mfg | O18: DFT | P18: 431 | Q18: EA | R18: 1.5801952 | S18: 17534 | T18: 272.75111 | U18: 0 | V18: 1.5801952 | W18: 46088 | X18: 46090
A19: =TRIM(B19) -> ASYHS30776W14P703 | B19: ASYHS30776W14P703 | C19: MB3B 5810692 AA | D19: P703 NUT WELD SUB ASSY | E19: PUR 5810776 AC | F19: ROW420-W14 | G19: A | H19: FRD01012 | J19: 703 | K19: MTL | M19: WIP | N19: Mfg | O19: DFT | P19: 1223 | Q19: EA | R19: 1.2749352 | S19: 61667 | T19: 959.26444 | U19: 0 | V19: 1.2749352 | W19: 46088 | X19: 46090
A20: =TRIM(B20) -> ASYHS40522W21W22 | B20: ASYHS40522W21W22 | C20: P1WB E280A54_55 BA | D20: P703 HS4 0522 W21W22 WELD ASY | E20: N1WB E10522A SUB ASSEMBLY | F20: ROW316-HS4-W21W22-MB4 | G20: A | H20: FRD01012 | J20: 703 | K20: MTL | M20: WIP | N20: Mfg | O20: DFT | P20: 1483 | Q20: EA | R20: 2.5112136 | S20: 37964 | T20: 590.55111 | U20: 0 | V20: 2.5112136 | W20: 46089 | X20: 46090
A21: =TRIM(B21) -> ASYHS49D59W16 | B21: ASYHS49D59W16 | C21: P1WB-E280A55-BA | D21: P703 HS4 9D59 W21 NUT SUB ASSY | E21: P1WB E279D59 AA | F21: ROW64A-W21-MB4 | G21: A | H21: FRD01012 | J21: 703 | K21: MTL | M21: WIP | N21: Mfg | O21: DFT | P21: 1142 | Q21: EA | R21: 3.9214938 | S21: 18721 | T21: 291.21556 | U21: 0 | V21: 3.9214938 | W21: 46090 | X21: 46090
A22: =TRIM(B22) -> ASYHS52C05W16P703 | B22: ASYHS52C05W16P703 | C22: MB3B 5810699 BA | D22: P703 HS5-2C05-W16 NUT WELD | E22: MB3B 58112C05 AA | F22: ROW158-W16-2-MB4 | G22: A | H22: FRD01000 | J22: 703 | K22: MTL | M22: WIP | N22: Mfg | O22: DFT | P22: 2974 | Q22: EA | R22: 3.1092164 | S22: 61490 | T22: 956.51111 | U22: 0 | V22: 3.1092164 | W22: 46090 | X22: 46090
A23: =TRIM(B23) -> ASYHS52K76W16P703 | B23: ASYHS52K76W16P703 | C23: MB3B 5810698 AE | D23: P703 HS5-2K76-W16 NUT WELD ASY | E23: MB3B 58112K76 A | F23: ROW160-W16-2-MB4 | G23: A | H23: FRD01000 | J23: 703 | K23: MTL | M23: WIP | N23: Mfg | O23: DFT | P23: 1979 | Q23: EA | R23: 2.0646126 | S23: 61620 | T23: 958.53333 | U23: 0 | V23: 2.0646126 | W23: 46089 | X23: 46090
A24: =TRIM(B24) -> ASYHS52K77W16P703 | B24: ASYHS52K77W16P703 | C24: MB3B 5810699 BA | D24: P703 HS5-2K77-W16 NUT WELD ASY | E24: MB3B 58112K77 A | F24: ROW161-W16-2-MB4 | G24: A | H24: FRD01000 | J24: 703 | K24: MTL | M24: WIP | N24: Mfg | O24: DFT | P24: 1313 | Q24: EA | R24: 1.3726971 | S24: 61490 | T24: 956.51111 | U24: 0 | V24: 1.3726971 | W24: 46088 | X24: 46090
A25: =TRIM(B25) -> ASYHS69A30W15P703 | B25: ASYHS69A30W15P703 | C25: N1WB E412A04 CB | D25: P703 HS6-9A30-W15 NUT WELD ASY | E25: N1WB E279A30 C | F25: ROW422 | G25: A | H25: FRD01000 | J25: 703 | K25: MTL | M25: WIP | N25: Mfg | O25: DFT | P25: 1099 | Q25: EA | R25: 3.9604238 | S25: 17839 | T25: 277.49556 | U25: 0 | V25: 3.9604238 | W25: 46090 | X25: 46090
A26: =TRIM(B26) -> ASYHS77A96W14P703 | B26: ASYHS77A96W14P703 | C26: MB3B 5810692 AA | D26: P703 HS7-7A96-W14 WELD ASY | E26: MB3B 58107A96 A | F26: ROW 442-W14 | G26: A | H26: FRD01000 | J26: 703 | K26: MTL | M26: WIP | N26: Mfg | O26: DFT | P26: 2295 | Q26: EA | R26: 2.3924581 | S26: 61667 | T26: 959.26444 | U26: 0 | V26: 2.3924581 | W26: 46089 | X26: 46090
A27: =TRIM(B27) -> ASYHS81753W2 | B27: ASYHS81753W2 | C27: KB3B 2610020 A | D27: HS8-1753-W2 NUT WELD SUB ASSY | E27: KB3B 2611753 A | F27: ROW 394-W2-MB4 | G27: A | H27: FRD01012 | J27: RAN | K27: MTL | M27: WIP | N27: Mfg | O27: DFT | P27: 3118 | Q27: EA | R27: 3.8105558 | S27: 52602 | T27: 818.25333 | U27: 0 | V27: 3.8105558 | W27: 46090 | X27: 46090
A28: =TRIM(B28) -> ASYMS10723OS | B28: ASYMS10723OS | C28: MB3B-10723-A/G | D28: P703 BATTERY TRAY SUB ASSEMBLY | E28: DETROIT TO XCEL | F28: ROW 129&130 | G28: A | J28: 703 | K28: MTL | M28: WIP | N28: Mfg | O28: DFT | P28: 951 | Q28: EA | R28: 3.240867 | S28: 18864 | T28: 293.44 | U28: 0 | V28: 3.240867 | W28: 46090 | X28: 46090
A29: =TRIM(B29) -> ASYMS20K50W14 | B29: ASYMS20K50W14 | C29: KB3B 2110692 AA | D29: MS2-0K50-W14 MIG WELD SUB ASSY | E29: KB3B 21000K50 A | F29: ROW284-W14-MB2 | G29: A | J29: RAN | K29: MTL | M29: WIP | N29: Mfg | O29: DFT | P29: 6604 | Q29: EA | R29: 2.680161 | S29: 158402 | T29: 2464.0311 | U29: 0 | V29: 2.680161 | W29: 46089 | X29: 46090
A30: =TRIM(B30) -> ASYPW20116W13HV | B30: ASYPW20116W13HV | C30: KB3B 2610110 AB | D30: PW2-0116-W13 STUD WELD SUB ASY | E30: KB3B 2610116 A | F30: ROW306-W13-MB4 HV | G30: A | H30: FRD01000 | J30: RAN | K30: MTL | M30: WIP | N30: Mfg | O30: DFT | P30: 585 | Q30: EA | R30: 2.1588486 | S30: 17420 | T30: 270.97778 | U30: 0 | V30: 2.1588486 | W30: 46089 | X30: 46090
A31: =TRIM(B31) -> ASYPW31530W1 | B31: ASYPW31530W1 | C31: KB3B 21021A40 AA | D31: PW3-1530-W1 NUT WELD SUB ASSY | E31: KB3B 2101530 A | F31: ROW303C-W1-MB4 | G31: A | H31: FRD01000 | J31: RAN | K31: MTL | M31: WIP | N31: Mfg | O31: DFT | P31: 628 | Q31: EA | R31: 2.1205709 | S31: 19038 | T31: 296.14667 | U31: 0 | V31: 2.1205709 | W31: 46089 | X31: 46090
A32: =TRIM(B32) -> ASYPW50723MS1 | B32: ASYPW50723MS1 | C32: MB3B 10723 A_G PIA 02 | D32: P703 PW5-0723-MIGSUB 1 SUBASY | E32: MB3B 10723 A&G PIA 02 | F32: ROW441-MIGSUB-1-MB4 | G32: A | H32: FRD01000 | J32: 703 | K32: MTL | M32: WIP | N32: Mfg | O32: DFT | P32: 332 | Q32: EA | R32: 1.068639 | S32: 19972 | T32: 310.67556 | U32: 0 | V32: 1.068639 | W32: 46088 | X32: 46090
A33: =TRIM(B33) -> ASYPW50K21W15P703 | B33: ASYPW50K21W15P703 | C33: N1WB E412A05 CB | D33: P703 PW5-0K20-W15-1 SUB ASSY | E33: N1WB E410K21 AA | F33: ROW301A-MB2 | G33: A | H33: FRD01000 | J33: 703 | K33: MTL | M33: WIP | N33: Mfg | O33: DFT | P33: 837 | Q33: EA | R33: 3.1431242 | S33: 17119 | T33: 266.29556 | U33: 0 | V33: 3.1431242 | W33: 46090 | X33: 46090
A34: =TRIM(B34) -> ASYW150786W16 | B34: ASYW150786W16 | C34: P1WB-E280A54_55 BA | D34: P703 W15 0786 W16 SUB ASY | E34: P1WB E10786 B | F34: ROW303H-W22-MB2-700 | G34: A | H34: FRD01012 | J34: 703 | K34: MTL | M34: WIP | N34: Mfg | O34: DFT | P34: 2099 | Q34: EA | R34: 3.6049188 | S34: 37431 | T34: 582.26 | U34: 0 | V34: 3.6049188 | W34: 46090 | X34: 46090
A35: =TRIM(B35) -> ASYW160A25W21 | B35: ASYW160A25W21 | C35: P1WB-E280A55-BA | D35: P703 W16 0A25 W22 SUB ASY | E35: P1WB E200A25 AA | F35: ROW352-W21-MB4 | G35: A | H35: FRD01012 | J35: 703 | K35: MTL | M35: WIP | N35: Mfg | O35: DFT | P35: 1002 | Q35: EA | R35: 3.3896903 | S35: 19003 | T35: 295.60222 | U35: 0 | V35: 3.3896903 | W35: 46090 | X35: 46090
A36: =TRIM(B36) -> ASYW20506W15 | B36: ASYW20506W15 | C36: KB3B 26403E32 AD | D36: W2-00506-W16 MIG WELD SUB ASSY | E36: KB3B 2640506 A | F36: ROW 162-W15-MB2 | G36: A | H36: FRD01000 | J36: RAN | K36: MTL | M36: WIP | N36: Mfg | O36: DFT | P36: 363 | Q36: EA | R36: 1.3863075 | S36: 16833 | T36: 261.84667 | U36: 0 | V36: 1.3863075 | W36: 46088 | X36: 46090
A37: =TRIM(B37) -> BLKBR58111K36 | B37: BLKBR58111K36 | D37: GAGE=.031" W=54.134 P=19.8819" | E37: BLK WT=11.34 LB RE INF FLR TNL | F37: WSS-M1A368-A14 CRDP800 50G50G | G37: A | J37: BRN | K37: MTL | M37: PC | N37: Mfg | O37: DFT | P37: 2911 | Q37: EA | R37: 3.3527853 | S37: 55815 | T37: 868.23333 | U37: 0 | V37: 3.3527853 | W37: 46090 | X37: 46090
A38: =TRIM(B38) -> BT1CC009 | B38: BT1CC009 | C38: BT1CC009 | D38: BT1CC HEADLINER BACK PLATE RH | E38: RST REFINE 85154947 | F38: 36819 | G38: A | H38: DAIM0101 | J38: GM | K38: PLA | M38: FGP | N38: Mfg | O38: DFT | P38: 33 | Q38: EA | R38: 3.3997253 | S38: 624 | T38: 9.7066667 | U38: 0 | V38: 3.3997253 | W38: 46090 | X38: 46090
A39: =TRIM(B39) -> C0240302 | B39: C0240302 | C39: 84489303 | D39: T1XX CC EXT BRKT LH | E39: 84489303 BATTLE CREEK | F39: DETROIT DOCK | G39: A | H39: XFNGBC | J39: GM | K39: MTL | M39: FGP | N39: Mfg | O39: DFT | P39: 11073 | Q39: EA | R39: 3.9111852 | S39: 182000 | T39: 2831.1111 | U39: 0 | V39: 3.9111852 | W39: 46090 | X39: 46090
A40: =TRIM(B40) -> DET17A040A | B40: DET17A040A | C40: MB3B-2610020-AA | D40: P703 JACK BRCKT | F40: ROW 267 MB2/2200 | G40: A | J40: 703 | K40: MTL | M40: WIP | N40: Mfg | O40: DFT | P40: 345 | Q40: EA | R40: 1.6343826 | S40: 13570 | T40: 211.08889 | U40: 0 | V40: 1.6343826 | W40: 46088 | X40: 46090
...

Sheet Sheet5
A1: Ship History for Mar 5, 2026 - FDDAT
A2: Cust Part# | B2: Internal Part# | C2: Part Desc | D2: ShipTo Cust# | E2: ShipTo Customer | F2: 2026-03-05
A3: 84533246 | B3: 84533246 | C3: T1XX PNL PUBX W/H FRT RH | D3: GMC01030 | E3: GM FLINT ASSEMBLY | F3: 90
D4: GMC01110 | E4: GM OSHAWA ASSEMBLY | F4: 270
A5: DET850109BU0A10N00L | B5: DET850109BU0A10N00L | C5: H61P RR OTR BRC FRMD L-ROW 259 | D5: XFNGXCEL | E5: X-CEL INDUSTRIES | F5: 3366
A6: N1WB E23943 UF3ZHE | B6: N1WB E23943 UF3ZHE | C6: P703 DOOR FRT DBL LH | D6: FRD01HRN | E6: FORD/HEARN INDUSTRIAL SERVICE | F6: 16
A7: 85058020 | B7: 85058020 | C7: BT1CC C-PILLAR UPR RH VALUE | D7: GMC01010 | E7: GM FACTORY ZERO | F7: 72
A8: MB3B 21016A23 AA | B8: MB3B 21016A23 AA | C8: P703 REINF D/PNL LH INR | D8: FRD01013 | E8: FORD MOTOR COMPANY MS0BA | F8: 560
A9: 68566341AB | B9: 68566341AB | C9: DT MCA CENTER BRACKET | D9: XFNGSHB1 | E9: FLEX N GATE SHELBY LLC | F9: 1044
A10: MB3B 5810699 BA | B10: MB3B 5810699 BA | C10: P703 CROSS MEMBER #3 LH | D10: FRD01015 | E10: FORD MOTOR COMPANY AP02A | F10: 650
A11: P1WB E280A54 BB | B11: P1WB E280A54 BB | C11: P703 PNL ASY BDY SD INR RH | D11: FRD01013 | E11: FORD MOTOR COMPANY MS0BA | F11: 270
A12: N1WB E27407 CL3ZHE | B12: N1WB E27407 CL3ZHE | C12: P703 DOOR REAR DBL LH | D12: FRD01HRN | E12: FORD/HEARN INDUSTRIAL SERVICE | F12: 16
A13: N1WB E106B46 AD | B13: N1WB E106B46 AD | C13: P703 SL ASY RR FLR CS FRT | D13: FRD01015 | E13: FORD MOTOR COMPANY AP02A | F13: 360
A14: N1WB E24397 CA31NB | B14: N1WB E24397 CA31NB | C14: P703 B PILLAR LH | D14: FRD01012 | E14: FORD MOTOR COMPANY AP02A | F14: 96
A15: MB3B 58016B28 AA | B15: MB3B 58016B28 AA | C15: U725 REINF D/PNL BRK MSTR CYL | D15: FRD01013 | E15: FORD MOTOR COMPANY MS0BA | F15: 3600
A16: N1WB E23942 BK1G1E | B16: N1WB E23942 BK1G1E | C16: P703 DOOR FRT DBL RH | D16: FRD01HRN | E16: FORD/HEARN INDUSTRIAL SERVICE | F16: 2
... A73: 84643220 | B73: 84643220 | C73: T1XX PNL PUBX W/H RR LH | D73: GMC01030 | E73: GM FLINT ASSEMBLY | F73: 270
D74: GMC01110 | E74: GM OSHAWA ASSEMBLY | F74: 270
A75: N1WB 17D568 EF3JA6 | B75: N1WB 17D568 EF3JA6 | C75: P703 RAIN SENSOR COVER | D75: FRD01012 | E75: FORD MOTOR COMPANY AP02A | F75: 240
A76: 84533245 | B76: 84533245 | C76: T1XX PNL PUBX W/H FRT LH | D76: GMC01110 | E76: GM OSHAWA ASSEMBLY | F76: 270
D77: GMC01030 | E77: GM FLINT ASSEMBLY | F77: 180
A78: DET850109BU0A07N00R | B78: DET850109BU0A07N00R | C78: H61P RR TOP PLT FD RH-ROW 256 | D78: XFNGXCEL | E78: X-CEL INDUSTRIES | F78: 3000
A79: N1WB E20171 AA | B79: N1WB E20171 AA | C79: P703 REINF DR RR FR | D79: FRD01013 | E79: FORD MOTOR COMPANY MS0BA | F79: 860
A80: MB3B 2610020 AB | B80: MB3B 2610020 AB | C80: P703 FLR ASY RR | D80: FRD01015 | E80: FORD MOTOR COMPANY AP02A | F80: 242
A81: R1WB E41018 CA | B81: R1WB E41018 CA | C81: P703 TAILGATE ASSY | D81: FRD01012 | E81: FORD MOTOR COMPANY AP02A | F81: 500
A82: MB3B 5801710 AA | B82: MB3B 5801710 AA | C82: U725 REINF DH SD PNL | D82: FRD01013 | E82: FORD MOTOR COMPANY MS0BA | F82: 3600
A83: T2DJ 16E166 AA | B83: T2DJ 16E166 AA | C83: U725 AGS 60TH ANNIVERSARY | D83: FRD01012 | E83: FORD MOTOR COMPANY AP02A | F83: 36
A84: 85746601 | B84: 85746601 | C84: BT1CC B-PILLAR UPPER RH | D84: GMC01010 | E84: GM FACTORY ZERO | F84: 48
A85: R1WB E291A34 MAA | B85: R1WB E291A34 MAA | C85: P703 BOX TOP RH | D85: FRD01012 | E85: FORD MOTOR COMPANY AP02A | F85: 480
A86: N1WB E31006 EB3ZHE | B86: N1WB E31006 EB3ZHE | C86: P703 PNL BDY SD RR CNR TR | D86: FRD01012 | E86: FORD MOTOR COMPANY AP02A | F86: 264
A87: 87868129 | B87: 87868129 | C87: BT1CC WT 40% DIVIDER W/O SUB | D87: GMC01010 | E87: GM FACTORY ZERO | F87: 66
A88: N1WB E24396 CA31NB | B88: N1WB E24396 CA31NB | C88: P703 B PILLAR RH | D88: FRD01012 | E88: FORD MOTOR COMPANY AP02A | F88: 192
A89: 85701332 | B89: 85701332 | C89: BT1CC C-PLR UPR RH RST/ REFINE | D89: GMC01010 | E89: GM FACTORY ZERO | F89: 24
... A157: N1WB E20170 AA | B157: N1WB E20170 AA | C157: P703 REINF DR RR FR | D157: FRD01013 | E157: FORD MOTOR COMPANY MS0BA | F157: 860
